ERROR 2021-10-14 11:22:45,810 log 753627 140083225310976 Internal Server Error: /admin/form_produksi/productionform/add/
Traceback (most recent call last):
  File "/home/Vieri/.local/lib/python3.6/site-packages/django/core/handlers/exception.py", line 47, in inner
    response = get_response(request)
  File "/home/Vieri/.local/lib/python3.6/site-packages/django/core/handlers/base.py", line 181, in _get_response
    response = wrapped_callback(request, *callback_args, **callback_kwargs)
  File "/home/Vieri/.local/lib/python3.6/site-packages/django/contrib/admin/options.py", line 614, in wrapper
    return self.admin_site.admin_view(view)(*args, **kwargs)
  File "/home/Vieri/.local/lib/python3.6/site-packages/django/utils/decorators.py", line 130, in _wrapped_view
    response = view_func(request, *args, **kwargs)
  File "/home/Vieri/.local/lib/python3.6/site-packages/django/views/decorators/cache.py", line 44, in _wrapped_view_func
    response = view_func(request, *args, **kwargs)
  File "/home/Vieri/.local/lib/python3.6/site-packages/django/contrib/admin/sites.py", line 233, in inner
    return view(request, *args, **kwargs)
  File "/home/Vieri/.local/lib/python3.6/site-packages/django/contrib/admin/options.py", line 1653, in add_view
    return self.changeform_view(request, None, form_url, extra_context)
  File "/home/Vieri/.local/lib/python3.6/site-packages/django/utils/decorators.py", line 43, in _wrapper
    return bound_method(*args, **kwargs)
  File "/home/Vieri/.local/lib/python3.6/site-packages/django/utils/decorators.py", line 130, in _wrapped_view
    response = view_func(request, *args, **kwargs)
  File "/home/Vieri/.local/lib/python3.6/site-packages/django/contrib/admin/options.py", line 1534, in changeform_view
    return self._changeform_view(request, object_id, form_url, extra_context)
  File "/home/Vieri/.local/lib/python3.6/site-packages/django/contrib/admin/options.py", line 1579, in _changeform_view
    if all_valid(formsets) and form_validated:
  File "/home/Vieri/.local/lib/python3.6/site-packages/monkeybiz/__init__.py", line 89, in wrapper
    return func(original_callable, *args, **kwargs)
  File "/home/Vieri/.local/lib/python3.6/site-packages/nested_admin/__init__.py", line 134, in all_valid
    if not original_all_valid(formsets):
  File "/home/Vieri/.local/lib/python3.6/site-packages/django/forms/formsets.py", line 464, in all_valid
    valid &= formset.is_valid()
  File "/home/Vieri/.local/lib/python3.6/site-packages/django/forms/formsets.py", line 308, in is_valid
    self.errors
  File "/home/Vieri/.local/lib/python3.6/site-packages/django/forms/formsets.py", line 288, in errors
    self.full_clean()
  File "/home/Vieri/.local/lib/python3.6/site-packages/django/forms/formsets.py", line 336, in full_clean
    form_errors = form.errors
  File "/home/Vieri/.local/lib/python3.6/site-packages/django/forms/forms.py", line 172, in errors
    self.full_clean()
  File "/home/Vieri/.local/lib/python3.6/site-packages/django/forms/forms.py", line 376, in full_clean
    self._post_clean()
  File "/home/Vieri/.local/lib/python3.6/site-packages/django/forms/models.py", line 405, in _post_clean
    self.instance.full_clean(exclude=exclude, validate_unique=False)
  File "/home/Vieri/.local/lib/python3.6/site-packages/django/db/models/base.py", line 1216, in full_clean
    self.clean()
  File "/home/Vieri/project_dir/oee_impc/form_produksi/models.py", line 220, in clean
    durasi_dt = calc_duration(self.waktu_mulai, self.waktu_selesai)
  File "/home/Vieri/project_dir/oee_impc/form_produksi/models.py", line 605, in calc_duration
    akhir = datetime.combine(dummy, selesai)
TypeError: combine() argument 2 must be datetime.time, not None
ERROR 2021-10-14 11:22:46,268 basehttp 753627 140083225310976 "POST /admin/form_produksi/productionform/add/ HTTP/1.1" 500 162460
ERROR 2021-10-14 11:23:39,887 log 753658 140391718762240 Internal Server Error: /admin/form_produksi/productionform/add/
Traceback (most recent call last):
  File "/home/Vieri/.local/lib/python3.6/site-packages/django/core/handlers/exception.py", line 47, in inner
    response = get_response(request)
  File "/home/Vieri/.local/lib/python3.6/site-packages/django/core/handlers/base.py", line 181, in _get_response
    response = wrapped_callback(request, *callback_args, **callback_kwargs)
  File "/home/Vieri/.local/lib/python3.6/site-packages/django/contrib/admin/options.py", line 614, in wrapper
    return self.admin_site.admin_view(view)(*args, **kwargs)
  File "/home/Vieri/.local/lib/python3.6/site-packages/django/utils/decorators.py", line 130, in _wrapped_view
    response = view_func(request, *args, **kwargs)
  File "/home/Vieri/.local/lib/python3.6/site-packages/django/views/decorators/cache.py", line 44, in _wrapped_view_func
    response = view_func(request, *args, **kwargs)
  File "/home/Vieri/.local/lib/python3.6/site-packages/django/contrib/admin/sites.py", line 233, in inner
    return view(request, *args, **kwargs)
  File "/home/Vieri/.local/lib/python3.6/site-packages/django/contrib/admin/options.py", line 1653, in add_view
    return self.changeform_view(request, None, form_url, extra_context)
  File "/home/Vieri/.local/lib/python3.6/site-packages/django/utils/decorators.py", line 43, in _wrapper
    return bound_method(*args, **kwargs)
  File "/home/Vieri/.local/lib/python3.6/site-packages/django/utils/decorators.py", line 130, in _wrapped_view
    response = view_func(request, *args, **kwargs)
  File "/home/Vieri/.local/lib/python3.6/site-packages/django/contrib/admin/options.py", line 1534, in changeform_view
    return self._changeform_view(request, object_id, form_url, extra_context)
  File "/home/Vieri/.local/lib/python3.6/site-packages/django/contrib/admin/options.py", line 1579, in _changeform_view
    if all_valid(formsets) and form_validated:
  File "/home/Vieri/.local/lib/python3.6/site-packages/monkeybiz/__init__.py", line 89, in wrapper
    return func(original_callable, *args, **kwargs)
  File "/home/Vieri/.local/lib/python3.6/site-packages/nested_admin/__init__.py", line 134, in all_valid
    if not original_all_valid(formsets):
  File "/home/Vieri/.local/lib/python3.6/site-packages/django/forms/formsets.py", line 464, in all_valid
    valid &= formset.is_valid()
  File "/home/Vieri/.local/lib/python3.6/site-packages/django/forms/formsets.py", line 308, in is_valid
    self.errors
  File "/home/Vieri/.local/lib/python3.6/site-packages/django/forms/formsets.py", line 288, in errors
    self.full_clean()
  File "/home/Vieri/.local/lib/python3.6/site-packages/django/forms/formsets.py", line 336, in full_clean
    form_errors = form.errors
  File "/home/Vieri/.local/lib/python3.6/site-packages/django/forms/forms.py", line 172, in errors
    self.full_clean()
  File "/home/Vieri/.local/lib/python3.6/site-packages/django/forms/forms.py", line 376, in full_clean
    self._post_clean()
  File "/home/Vieri/.local/lib/python3.6/site-packages/django/forms/models.py", line 405, in _post_clean
    self.instance.full_clean(exclude=exclude, validate_unique=False)
  File "/home/Vieri/.local/lib/python3.6/site-packages/django/db/models/base.py", line 1216, in full_clean
    self.clean()
  File "/home/Vieri/project_dir/oee_impc/form_produksi/models.py", line 220, in clean
    durasi_dt = calc_duration(self.waktu_mulai, self.waktu_selesai)
  File "/home/Vieri/project_dir/oee_impc/form_produksi/models.py", line 605, in calc_duration
    akhir = datetime.combine(dummy, selesai)
TypeError: combine() argument 2 must be datetime.time, not None
ERROR 2021-10-14 11:23:40,298 basehttp 753658 140391718762240 "POST /admin/form_produksi/productionform/add/ HTTP/1.1" 500 162480
ERROR 2021-10-14 11:24:00,070 log 753658 140391710369536 Internal Server Error: /admin/form_produksi/productionform/19311/change/
Traceback (most recent call last):
  File "/home/Vieri/.local/lib/python3.6/site-packages/django/core/handlers/exception.py", line 47, in inner
    response = get_response(request)
  File "/home/Vieri/.local/lib/python3.6/site-packages/django/core/handlers/base.py", line 181, in _get_response
    response = wrapped_callback(request, *callback_args, **callback_kwargs)
  File "/home/Vieri/.local/lib/python3.6/site-packages/django/contrib/admin/options.py", line 614, in wrapper
    return self.admin_site.admin_view(view)(*args, **kwargs)
  File "/home/Vieri/.local/lib/python3.6/site-packages/django/utils/decorators.py", line 130, in _wrapped_view
    response = view_func(request, *args, **kwargs)
  File "/home/Vieri/.local/lib/python3.6/site-packages/django/views/decorators/cache.py", line 44, in _wrapped_view_func
    response = view_func(request, *args, **kwargs)
  File "/home/Vieri/.local/lib/python3.6/site-packages/django/contrib/admin/sites.py", line 233, in inner
    return view(request, *args, **kwargs)
  File "/home/Vieri/.local/lib/python3.6/site-packages/django/contrib/admin/options.py", line 1656, in change_view
    return self.changeform_view(request, object_id, form_url, extra_context)
  File "/home/Vieri/.local/lib/python3.6/site-packages/django/utils/decorators.py", line 43, in _wrapper
    return bound_method(*args, **kwargs)
  File "/home/Vieri/.local/lib/python3.6/site-packages/django/utils/decorators.py", line 130, in _wrapped_view
    response = view_func(request, *args, **kwargs)
  File "/home/Vieri/.local/lib/python3.6/site-packages/django/contrib/admin/options.py", line 1534, in changeform_view
    return self._changeform_view(request, object_id, form_url, extra_context)
  File "/home/Vieri/.local/lib/python3.6/site-packages/django/contrib/admin/options.py", line 1579, in _changeform_view
    if all_valid(formsets) and form_validated:
  File "/home/Vieri/.local/lib/python3.6/site-packages/monkeybiz/__init__.py", line 89, in wrapper
    return func(original_callable, *args, **kwargs)
  File "/home/Vieri/.local/lib/python3.6/site-packages/nested_admin/__init__.py", line 134, in all_valid
    if not original_all_valid(formsets):
  File "/home/Vieri/.local/lib/python3.6/site-packages/django/forms/formsets.py", line 464, in all_valid
    valid &= formset.is_valid()
  File "/home/Vieri/.local/lib/python3.6/site-packages/django/forms/formsets.py", line 308, in is_valid
    self.errors
  File "/home/Vieri/.local/lib/python3.6/site-packages/django/forms/formsets.py", line 288, in errors
    self.full_clean()
  File "/home/Vieri/.local/lib/python3.6/site-packages/django/forms/formsets.py", line 336, in full_clean
    form_errors = form.errors
  File "/home/Vieri/.local/lib/python3.6/site-packages/django/forms/forms.py", line 172, in errors
    self.full_clean()
  File "/home/Vieri/.local/lib/python3.6/site-packages/django/forms/forms.py", line 376, in full_clean
    self._post_clean()
  File "/home/Vieri/.local/lib/python3.6/site-packages/django/forms/models.py", line 405, in _post_clean
    self.instance.full_clean(exclude=exclude, validate_unique=False)
  File "/home/Vieri/.local/lib/python3.6/site-packages/django/db/models/base.py", line 1216, in full_clean
    self.clean()
  File "/home/Vieri/project_dir/oee_impc/form_produksi/models.py", line 220, in clean
    durasi_dt = calc_duration(self.waktu_mulai, self.waktu_selesai)
  File "/home/Vieri/project_dir/oee_impc/form_produksi/models.py", line 605, in calc_duration
    akhir = datetime.combine(dummy, selesai)
TypeError: combine() argument 2 must be datetime.time, not None
ERROR 2021-10-14 11:24:00,382 basehttp 753658 140391710369536 "POST /admin/form_produksi/productionform/19311/change/ HTTP/1.1" 500 163209
ERROR 2021-10-14 11:32:33,048 log 753771 140221337294592 Internal Server Error: /admin/form_produksi/productionform/19311/change/
Traceback (most recent call last):
  File "/home/Vieri/.local/lib/python3.6/site-packages/django/core/handlers/exception.py", line 47, in inner
    response = get_response(request)
  File "/home/Vieri/.local/lib/python3.6/site-packages/django/core/handlers/base.py", line 181, in _get_response
    response = wrapped_callback(request, *callback_args, **callback_kwargs)
  File "/home/Vieri/.local/lib/python3.6/site-packages/django/contrib/admin/options.py", line 614, in wrapper
    return self.admin_site.admin_view(view)(*args, **kwargs)
  File "/home/Vieri/.local/lib/python3.6/site-packages/django/utils/decorators.py", line 130, in _wrapped_view
    response = view_func(request, *args, **kwargs)
  File "/home/Vieri/.local/lib/python3.6/site-packages/django/views/decorators/cache.py", line 44, in _wrapped_view_func
    response = view_func(request, *args, **kwargs)
  File "/home/Vieri/.local/lib/python3.6/site-packages/django/contrib/admin/sites.py", line 233, in inner
    return view(request, *args, **kwargs)
  File "/home/Vieri/.local/lib/python3.6/site-packages/django/contrib/admin/options.py", line 1656, in change_view
    return self.changeform_view(request, object_id, form_url, extra_context)
  File "/home/Vieri/.local/lib/python3.6/site-packages/django/utils/decorators.py", line 43, in _wrapper
    return bound_method(*args, **kwargs)
  File "/home/Vieri/.local/lib/python3.6/site-packages/django/utils/decorators.py", line 130, in _wrapped_view
    response = view_func(request, *args, **kwargs)
  File "/home/Vieri/.local/lib/python3.6/site-packages/django/contrib/admin/options.py", line 1534, in changeform_view
    return self._changeform_view(request, object_id, form_url, extra_context)
  File "/home/Vieri/.local/lib/python3.6/site-packages/django/contrib/admin/options.py", line 1579, in _changeform_view
    if all_valid(formsets) and form_validated:
  File "/home/Vieri/.local/lib/python3.6/site-packages/monkeybiz/__init__.py", line 89, in wrapper
    return func(original_callable, *args, **kwargs)
  File "/home/Vieri/.local/lib/python3.6/site-packages/nested_admin/__init__.py", line 134, in all_valid
    if not original_all_valid(formsets):
  File "/home/Vieri/.local/lib/python3.6/site-packages/django/forms/formsets.py", line 464, in all_valid
    valid &= formset.is_valid()
  File "/home/Vieri/.local/lib/python3.6/site-packages/django/forms/formsets.py", line 308, in is_valid
    self.errors
  File "/home/Vieri/.local/lib/python3.6/site-packages/django/forms/formsets.py", line 288, in errors
    self.full_clean()
  File "/home/Vieri/.local/lib/python3.6/site-packages/django/forms/formsets.py", line 336, in full_clean
    form_errors = form.errors
  File "/home/Vieri/.local/lib/python3.6/site-packages/django/forms/forms.py", line 172, in errors
    self.full_clean()
  File "/home/Vieri/.local/lib/python3.6/site-packages/django/forms/forms.py", line 376, in full_clean
    self._post_clean()
  File "/home/Vieri/.local/lib/python3.6/site-packages/django/forms/models.py", line 405, in _post_clean
    self.instance.full_clean(exclude=exclude, validate_unique=False)
  File "/home/Vieri/.local/lib/python3.6/site-packages/django/db/models/base.py", line 1216, in full_clean
    self.clean()
  File "/home/Vieri/project_dir/oee_impc/form_produksi/models.py", line 221, in clean
    if durasi_form < durasi_dt :
NameError: name 'durasi_dt' is not defined
ERROR 2021-10-14 11:32:33,909 basehttp 753771 140221337294592 "POST /admin/form_produksi/productionform/19311/change/ HTTP/1.1" 500 158589
ERROR 2021-10-14 11:39:10,757 log 753816 140020161705728 Internal Server Error: /admin/form_produksi/productionform/add/
Traceback (most recent call last):
  File "/home/Vieri/.local/lib/python3.6/site-packages/django/forms/models.py", line 405, in _post_clean
    self.instance.full_clean(exclude=exclude, validate_unique=False)
  File "/home/Vieri/.local/lib/python3.6/site-packages/django/db/models/base.py", line 1231, in full_clean
    raise ValidationError(errors)
django.core.exceptions.ValidationError: {'user_group': ['This field cannot be null.']}

During handling of the above exception, another exception occurred:

Traceback (most recent call last):
  File "/home/Vieri/.local/lib/python3.6/site-packages/django/core/handlers/exception.py", line 47, in inner
    response = get_response(request)
  File "/home/Vieri/.local/lib/python3.6/site-packages/django/core/handlers/base.py", line 181, in _get_response
    response = wrapped_callback(request, *callback_args, **callback_kwargs)
  File "/home/Vieri/.local/lib/python3.6/site-packages/django/contrib/admin/options.py", line 614, in wrapper
    return self.admin_site.admin_view(view)(*args, **kwargs)
  File "/home/Vieri/.local/lib/python3.6/site-packages/django/utils/decorators.py", line 130, in _wrapped_view
    response = view_func(request, *args, **kwargs)
  File "/home/Vieri/.local/lib/python3.6/site-packages/django/views/decorators/cache.py", line 44, in _wrapped_view_func
    response = view_func(request, *args, **kwargs)
  File "/home/Vieri/.local/lib/python3.6/site-packages/django/contrib/admin/sites.py", line 233, in inner
    return view(request, *args, **kwargs)
  File "/home/Vieri/.local/lib/python3.6/site-packages/django/contrib/admin/options.py", line 1653, in add_view
    return self.changeform_view(request, None, form_url, extra_context)
  File "/home/Vieri/.local/lib/python3.6/site-packages/django/utils/decorators.py", line 43, in _wrapper
    return bound_method(*args, **kwargs)
  File "/home/Vieri/.local/lib/python3.6/site-packages/django/utils/decorators.py", line 130, in _wrapped_view
    response = view_func(request, *args, **kwargs)
  File "/home/Vieri/.local/lib/python3.6/site-packages/django/contrib/admin/options.py", line 1534, in changeform_view
    return self._changeform_view(request, object_id, form_url, extra_context)
  File "/home/Vieri/.local/lib/python3.6/site-packages/django/contrib/admin/options.py", line 1573, in _changeform_view
    form_validated = form.is_valid()
  File "/home/Vieri/.local/lib/python3.6/site-packages/django/forms/forms.py", line 177, in is_valid
    return self.is_bound and not self.errors
  File "/home/Vieri/.local/lib/python3.6/site-packages/django/forms/forms.py", line 172, in errors
    self.full_clean()
  File "/home/Vieri/.local/lib/python3.6/site-packages/django/forms/forms.py", line 376, in full_clean
    self._post_clean()
  File "/home/Vieri/.local/lib/python3.6/site-packages/django/forms/models.py", line 407, in _post_clean
    self._update_errors(e)
  File "/home/Vieri/.local/lib/python3.6/site-packages/django/forms/models.py", line 381, in _update_errors
    self.add_error(None, errors)
  File "/home/Vieri/.local/lib/python3.6/site-packages/django/forms/forms.py", line 346, in add_error
    "'%s' has no field named '%s'." % (self.__class__.__name__, field))
ValueError: 'ProductionFormForm' has no field named 'user_group'.
ERROR 2021-10-14 11:39:10,887 basehttp 753816 140020161705728 "POST /admin/form_produksi/productionform/add/?_changelist_filters=normalized_date__month%3D10%26normalized_date__year%3D2021 HTTP/1.1" 500 164668
ERROR 2021-10-14 11:39:15,939 log 753816 140020161705728 Internal Server Error: /admin/form_produksi/productionform/add/
Traceback (most recent call last):
  File "/home/Vieri/.local/lib/python3.6/site-packages/django/forms/models.py", line 405, in _post_clean
    self.instance.full_clean(exclude=exclude, validate_unique=False)
  File "/home/Vieri/.local/lib/python3.6/site-packages/django/db/models/base.py", line 1231, in full_clean
    raise ValidationError(errors)
django.core.exceptions.ValidationError: {'user_group': ['This field cannot be null.']}

During handling of the above exception, another exception occurred:

Traceback (most recent call last):
  File "/home/Vieri/.local/lib/python3.6/site-packages/django/core/handlers/exception.py", line 47, in inner
    response = get_response(request)
  File "/home/Vieri/.local/lib/python3.6/site-packages/django/core/handlers/base.py", line 181, in _get_response
    response = wrapped_callback(request, *callback_args, **callback_kwargs)
  File "/home/Vieri/.local/lib/python3.6/site-packages/django/contrib/admin/options.py", line 614, in wrapper
    return self.admin_site.admin_view(view)(*args, **kwargs)
  File "/home/Vieri/.local/lib/python3.6/site-packages/django/utils/decorators.py", line 130, in _wrapped_view
    response = view_func(request, *args, **kwargs)
  File "/home/Vieri/.local/lib/python3.6/site-packages/django/views/decorators/cache.py", line 44, in _wrapped_view_func
    response = view_func(request, *args, **kwargs)
  File "/home/Vieri/.local/lib/python3.6/site-packages/django/contrib/admin/sites.py", line 233, in inner
    return view(request, *args, **kwargs)
  File "/home/Vieri/.local/lib/python3.6/site-packages/django/contrib/admin/options.py", line 1653, in add_view
    return self.changeform_view(request, None, form_url, extra_context)
  File "/home/Vieri/.local/lib/python3.6/site-packages/django/utils/decorators.py", line 43, in _wrapper
    return bound_method(*args, **kwargs)
  File "/home/Vieri/.local/lib/python3.6/site-packages/django/utils/decorators.py", line 130, in _wrapped_view
    response = view_func(request, *args, **kwargs)
  File "/home/Vieri/.local/lib/python3.6/site-packages/django/contrib/admin/options.py", line 1534, in changeform_view
    return self._changeform_view(request, object_id, form_url, extra_context)
  File "/home/Vieri/.local/lib/python3.6/site-packages/django/contrib/admin/options.py", line 1573, in _changeform_view
    form_validated = form.is_valid()
  File "/home/Vieri/.local/lib/python3.6/site-packages/django/forms/forms.py", line 177, in is_valid
    return self.is_bound and not self.errors
  File "/home/Vieri/.local/lib/python3.6/site-packages/django/forms/forms.py", line 172, in errors
    self.full_clean()
  File "/home/Vieri/.local/lib/python3.6/site-packages/django/forms/forms.py", line 376, in full_clean
    self._post_clean()
  File "/home/Vieri/.local/lib/python3.6/site-packages/django/forms/models.py", line 407, in _post_clean
    self._update_errors(e)
  File "/home/Vieri/.local/lib/python3.6/site-packages/django/forms/models.py", line 381, in _update_errors
    self.add_error(None, errors)
  File "/home/Vieri/.local/lib/python3.6/site-packages/django/forms/forms.py", line 346, in add_error
    "'%s' has no field named '%s'." % (self.__class__.__name__, field))
ValueError: 'ProductionFormForm' has no field named 'user_group'.
ERROR 2021-10-14 11:39:16,016 basehttp 753816 140020161705728 "POST /admin/form_produksi/productionform/add/?_changelist_filters=normalized_date__month%3D10%26normalized_date__year%3D2021 HTTP/1.1" 500 164668
ERROR 2021-10-14 11:39:48,226 log 753816 140020707989248 Internal Server Error: /admin/form_produksi/productionform/add/
Traceback (most recent call last):
  File "/home/Vieri/.local/lib/python3.6/site-packages/django/forms/models.py", line 405, in _post_clean
    self.instance.full_clean(exclude=exclude, validate_unique=False)
  File "/home/Vieri/.local/lib/python3.6/site-packages/django/db/models/base.py", line 1231, in full_clean
    raise ValidationError(errors)
django.core.exceptions.ValidationError: {'user_group': ['This field cannot be null.']}

During handling of the above exception, another exception occurred:

Traceback (most recent call last):
  File "/home/Vieri/.local/lib/python3.6/site-packages/django/core/handlers/exception.py", line 47, in inner
    response = get_response(request)
  File "/home/Vieri/.local/lib/python3.6/site-packages/django/core/handlers/base.py", line 181, in _get_response
    response = wrapped_callback(request, *callback_args, **callback_kwargs)
  File "/home/Vieri/.local/lib/python3.6/site-packages/django/contrib/admin/options.py", line 614, in wrapper
    return self.admin_site.admin_view(view)(*args, **kwargs)
  File "/home/Vieri/.local/lib/python3.6/site-packages/django/utils/decorators.py", line 130, in _wrapped_view
    response = view_func(request, *args, **kwargs)
  File "/home/Vieri/.local/lib/python3.6/site-packages/django/views/decorators/cache.py", line 44, in _wrapped_view_func
    response = view_func(request, *args, **kwargs)
  File "/home/Vieri/.local/lib/python3.6/site-packages/django/contrib/admin/sites.py", line 233, in inner
    return view(request, *args, **kwargs)
  File "/home/Vieri/.local/lib/python3.6/site-packages/django/contrib/admin/options.py", line 1653, in add_view
    return self.changeform_view(request, None, form_url, extra_context)
  File "/home/Vieri/.local/lib/python3.6/site-packages/django/utils/decorators.py", line 43, in _wrapper
    return bound_method(*args, **kwargs)
  File "/home/Vieri/.local/lib/python3.6/site-packages/django/utils/decorators.py", line 130, in _wrapped_view
    response = view_func(request, *args, **kwargs)
  File "/home/Vieri/.local/lib/python3.6/site-packages/django/contrib/admin/options.py", line 1534, in changeform_view
    return self._changeform_view(request, object_id, form_url, extra_context)
  File "/home/Vieri/.local/lib/python3.6/site-packages/django/contrib/admin/options.py", line 1573, in _changeform_view
    form_validated = form.is_valid()
  File "/home/Vieri/.local/lib/python3.6/site-packages/django/forms/forms.py", line 177, in is_valid
    return self.is_bound and not self.errors
  File "/home/Vieri/.local/lib/python3.6/site-packages/django/forms/forms.py", line 172, in errors
    self.full_clean()
  File "/home/Vieri/.local/lib/python3.6/site-packages/django/forms/forms.py", line 376, in full_clean
    self._post_clean()
  File "/home/Vieri/.local/lib/python3.6/site-packages/django/forms/models.py", line 407, in _post_clean
    self._update_errors(e)
  File "/home/Vieri/.local/lib/python3.6/site-packages/django/forms/models.py", line 381, in _update_errors
    self.add_error(None, errors)
  File "/home/Vieri/.local/lib/python3.6/site-packages/django/forms/forms.py", line 346, in add_error
    "'%s' has no field named '%s'." % (self.__class__.__name__, field))
ValueError: 'ProductionFormForm' has no field named 'user_group'.
ERROR 2021-10-14 11:39:48,350 basehttp 753816 140020707989248 "POST /admin/form_produksi/productionform/add/?_changelist_filters=normalized_date__month%3D10%26normalized_date__year%3D2021 HTTP/1.1" 500 164668
ERROR 2021-10-14 11:42:24,144 log 753816 140020724774656 Internal Server Error: /admin/form_produksi/productionform/add/
Traceback (most recent call last):
  File "/home/Vieri/.local/lib/python3.6/site-packages/django/forms/models.py", line 405, in _post_clean
    self.instance.full_clean(exclude=exclude, validate_unique=False)
  File "/home/Vieri/.local/lib/python3.6/site-packages/django/db/models/base.py", line 1231, in full_clean
    raise ValidationError(errors)
django.core.exceptions.ValidationError: {'user_group': ['This field cannot be null.']}

During handling of the above exception, another exception occurred:

Traceback (most recent call last):
  File "/home/Vieri/.local/lib/python3.6/site-packages/django/core/handlers/exception.py", line 47, in inner
    response = get_response(request)
  File "/home/Vieri/.local/lib/python3.6/site-packages/django/core/handlers/base.py", line 181, in _get_response
    response = wrapped_callback(request, *callback_args, **callback_kwargs)
  File "/home/Vieri/.local/lib/python3.6/site-packages/django/contrib/admin/options.py", line 614, in wrapper
    return self.admin_site.admin_view(view)(*args, **kwargs)
  File "/home/Vieri/.local/lib/python3.6/site-packages/django/utils/decorators.py", line 130, in _wrapped_view
    response = view_func(request, *args, **kwargs)
  File "/home/Vieri/.local/lib/python3.6/site-packages/django/views/decorators/cache.py", line 44, in _wrapped_view_func
    response = view_func(request, *args, **kwargs)
  File "/home/Vieri/.local/lib/python3.6/site-packages/django/contrib/admin/sites.py", line 233, in inner
    return view(request, *args, **kwargs)
  File "/home/Vieri/.local/lib/python3.6/site-packages/django/contrib/admin/options.py", line 1653, in add_view
    return self.changeform_view(request, None, form_url, extra_context)
  File "/home/Vieri/.local/lib/python3.6/site-packages/django/utils/decorators.py", line 43, in _wrapper
    return bound_method(*args, **kwargs)
  File "/home/Vieri/.local/lib/python3.6/site-packages/django/utils/decorators.py", line 130, in _wrapped_view
    response = view_func(request, *args, **kwargs)
  File "/home/Vieri/.local/lib/python3.6/site-packages/django/contrib/admin/options.py", line 1534, in changeform_view
    return self._changeform_view(request, object_id, form_url, extra_context)
  File "/home/Vieri/.local/lib/python3.6/site-packages/django/contrib/admin/options.py", line 1573, in _changeform_view
    form_validated = form.is_valid()
  File "/home/Vieri/.local/lib/python3.6/site-packages/django/forms/forms.py", line 177, in is_valid
    return self.is_bound and not self.errors
  File "/home/Vieri/.local/lib/python3.6/site-packages/django/forms/forms.py", line 172, in errors
    self.full_clean()
  File "/home/Vieri/.local/lib/python3.6/site-packages/django/forms/forms.py", line 376, in full_clean
    self._post_clean()
  File "/home/Vieri/.local/lib/python3.6/site-packages/django/forms/models.py", line 407, in _post_clean
    self._update_errors(e)
  File "/home/Vieri/.local/lib/python3.6/site-packages/django/forms/models.py", line 381, in _update_errors
    self.add_error(None, errors)
  File "/home/Vieri/.local/lib/python3.6/site-packages/django/forms/forms.py", line 346, in add_error
    "'%s' has no field named '%s'." % (self.__class__.__name__, field))
ValueError: 'ProductionFormForm' has no field named 'user_group'.
ERROR 2021-10-14 11:42:24,256 basehttp 753816 140020724774656 "POST /admin/form_produksi/productionform/add/ HTTP/1.1" 500 151334
ERROR 2021-10-14 11:45:29,498 log 753816 140020724774656 Internal Server Error: /admin/form_produksi/productionform/add/
Traceback (most recent call last):
  File "/home/Vieri/.local/lib/python3.6/site-packages/django/forms/models.py", line 405, in _post_clean
    self.instance.full_clean(exclude=exclude, validate_unique=False)
  File "/home/Vieri/.local/lib/python3.6/site-packages/django/db/models/base.py", line 1231, in full_clean
    raise ValidationError(errors)
django.core.exceptions.ValidationError: {'user_group': ['This field cannot be null.'], 'no_kk': ['This field cannot be null.']}

During handling of the above exception, another exception occurred:

Traceback (most recent call last):
  File "/home/Vieri/.local/lib/python3.6/site-packages/django/core/handlers/exception.py", line 47, in inner
    response = get_response(request)
  File "/home/Vieri/.local/lib/python3.6/site-packages/django/core/handlers/base.py", line 181, in _get_response
    response = wrapped_callback(request, *callback_args, **callback_kwargs)
  File "/home/Vieri/.local/lib/python3.6/site-packages/django/contrib/admin/options.py", line 614, in wrapper
    return self.admin_site.admin_view(view)(*args, **kwargs)
  File "/home/Vieri/.local/lib/python3.6/site-packages/django/utils/decorators.py", line 130, in _wrapped_view
    response = view_func(request, *args, **kwargs)
  File "/home/Vieri/.local/lib/python3.6/site-packages/django/views/decorators/cache.py", line 44, in _wrapped_view_func
    response = view_func(request, *args, **kwargs)
  File "/home/Vieri/.local/lib/python3.6/site-packages/django/contrib/admin/sites.py", line 233, in inner
    return view(request, *args, **kwargs)
  File "/home/Vieri/.local/lib/python3.6/site-packages/django/contrib/admin/options.py", line 1653, in add_view
    return self.changeform_view(request, None, form_url, extra_context)
  File "/home/Vieri/.local/lib/python3.6/site-packages/django/utils/decorators.py", line 43, in _wrapper
    return bound_method(*args, **kwargs)
  File "/home/Vieri/.local/lib/python3.6/site-packages/django/utils/decorators.py", line 130, in _wrapped_view
    response = view_func(request, *args, **kwargs)
  File "/home/Vieri/.local/lib/python3.6/site-packages/django/contrib/admin/options.py", line 1534, in changeform_view
    return self._changeform_view(request, object_id, form_url, extra_context)
  File "/home/Vieri/.local/lib/python3.6/site-packages/django/contrib/admin/options.py", line 1573, in _changeform_view
    form_validated = form.is_valid()
  File "/home/Vieri/.local/lib/python3.6/site-packages/django/forms/forms.py", line 177, in is_valid
    return self.is_bound and not self.errors
  File "/home/Vieri/.local/lib/python3.6/site-packages/django/forms/forms.py", line 172, in errors
    self.full_clean()
  File "/home/Vieri/.local/lib/python3.6/site-packages/django/forms/forms.py", line 376, in full_clean
    self._post_clean()
  File "/home/Vieri/.local/lib/python3.6/site-packages/django/forms/models.py", line 407, in _post_clean
    self._update_errors(e)
  File "/home/Vieri/.local/lib/python3.6/site-packages/django/forms/models.py", line 381, in _update_errors
    self.add_error(None, errors)
  File "/home/Vieri/.local/lib/python3.6/site-packages/django/forms/forms.py", line 346, in add_error
    "'%s' has no field named '%s'." % (self.__class__.__name__, field))
ValueError: 'ProductionFormForm' has no field named 'user_group'.
ERROR 2021-10-14 11:45:29,756 basehttp 753816 140020724774656 "POST /admin/form_produksi/productionform/add/ HTTP/1.1" 500 152261
WARNING 2021-10-14 11:48:04,883 basehttp 753816 140020724774656 "Z¥     " 400 -
ERROR 2021-10-14 11:49:22,543 log 753816 140020707989248 Internal Server Error: /admin/form_produksi/productionform/add/
Traceback (most recent call last):
  File "/home/Vieri/.local/lib/python3.6/site-packages/django/forms/models.py", line 405, in _post_clean
    self.instance.full_clean(exclude=exclude, validate_unique=False)
  File "/home/Vieri/.local/lib/python3.6/site-packages/django/db/models/base.py", line 1231, in full_clean
    raise ValidationError(errors)
django.core.exceptions.ValidationError: {'user_group': ['This field cannot be null.']}

During handling of the above exception, another exception occurred:

Traceback (most recent call last):
  File "/home/Vieri/.local/lib/python3.6/site-packages/django/core/handlers/exception.py", line 47, in inner
    response = get_response(request)
  File "/home/Vieri/.local/lib/python3.6/site-packages/django/core/handlers/base.py", line 181, in _get_response
    response = wrapped_callback(request, *callback_args, **callback_kwargs)
  File "/home/Vieri/.local/lib/python3.6/site-packages/django/contrib/admin/options.py", line 614, in wrapper
    return self.admin_site.admin_view(view)(*args, **kwargs)
  File "/home/Vieri/.local/lib/python3.6/site-packages/django/utils/decorators.py", line 130, in _wrapped_view
    response = view_func(request, *args, **kwargs)
  File "/home/Vieri/.local/lib/python3.6/site-packages/django/views/decorators/cache.py", line 44, in _wrapped_view_func
    response = view_func(request, *args, **kwargs)
  File "/home/Vieri/.local/lib/python3.6/site-packages/django/contrib/admin/sites.py", line 233, in inner
    return view(request, *args, **kwargs)
  File "/home/Vieri/.local/lib/python3.6/site-packages/django/contrib/admin/options.py", line 1653, in add_view
    return self.changeform_view(request, None, form_url, extra_context)
  File "/home/Vieri/.local/lib/python3.6/site-packages/django/utils/decorators.py", line 43, in _wrapper
    return bound_method(*args, **kwargs)
  File "/home/Vieri/.local/lib/python3.6/site-packages/django/utils/decorators.py", line 130, in _wrapped_view
    response = view_func(request, *args, **kwargs)
  File "/home/Vieri/.local/lib/python3.6/site-packages/django/contrib/admin/options.py", line 1534, in changeform_view
    return self._changeform_view(request, object_id, form_url, extra_context)
  File "/home/Vieri/.local/lib/python3.6/site-packages/django/contrib/admin/options.py", line 1573, in _changeform_view
    form_validated = form.is_valid()
  File "/home/Vieri/.local/lib/python3.6/site-packages/django/forms/forms.py", line 177, in is_valid
    return self.is_bound and not self.errors
  File "/home/Vieri/.local/lib/python3.6/site-packages/django/forms/forms.py", line 172, in errors
    self.full_clean()
  File "/home/Vieri/.local/lib/python3.6/site-packages/django/forms/forms.py", line 376, in full_clean
    self._post_clean()
  File "/home/Vieri/.local/lib/python3.6/site-packages/django/forms/models.py", line 407, in _post_clean
    self._update_errors(e)
  File "/home/Vieri/.local/lib/python3.6/site-packages/django/forms/models.py", line 381, in _update_errors
    self.add_error(None, errors)
  File "/home/Vieri/.local/lib/python3.6/site-packages/django/forms/forms.py", line 346, in add_error
    "'%s' has no field named '%s'." % (self.__class__.__name__, field))
ValueError: 'ProductionFormForm' has no field named 'user_group'.
ERROR 2021-10-14 11:49:22,679 basehttp 753816 140020707989248 "POST /admin/form_produksi/productionform/add/ HTTP/1.1" 500 151334
ERROR 2021-10-14 11:51:30,489 log 753816 140020707989248 Internal Server Error: /admin/form_produksi/productionform/add/
Traceback (most recent call last):
  File "/home/Vieri/.local/lib/python3.6/site-packages/django/forms/models.py", line 405, in _post_clean
    self.instance.full_clean(exclude=exclude, validate_unique=False)
  File "/home/Vieri/.local/lib/python3.6/site-packages/django/db/models/base.py", line 1231, in full_clean
    raise ValidationError(errors)
django.core.exceptions.ValidationError: {'start_time': ['This field cannot be null.'], 'user_group': ['This field cannot be null.']}

During handling of the above exception, another exception occurred:

Traceback (most recent call last):
  File "/home/Vieri/.local/lib/python3.6/site-packages/django/core/handlers/exception.py", line 47, in inner
    response = get_response(request)
  File "/home/Vieri/.local/lib/python3.6/site-packages/django/core/handlers/base.py", line 181, in _get_response
    response = wrapped_callback(request, *callback_args, **callback_kwargs)
  File "/home/Vieri/.local/lib/python3.6/site-packages/django/contrib/admin/options.py", line 614, in wrapper
    return self.admin_site.admin_view(view)(*args, **kwargs)
  File "/home/Vieri/.local/lib/python3.6/site-packages/django/utils/decorators.py", line 130, in _wrapped_view
    response = view_func(request, *args, **kwargs)
  File "/home/Vieri/.local/lib/python3.6/site-packages/django/views/decorators/cache.py", line 44, in _wrapped_view_func
    response = view_func(request, *args, **kwargs)
  File "/home/Vieri/.local/lib/python3.6/site-packages/django/contrib/admin/sites.py", line 233, in inner
    return view(request, *args, **kwargs)
  File "/home/Vieri/.local/lib/python3.6/site-packages/django/contrib/admin/options.py", line 1653, in add_view
    return self.changeform_view(request, None, form_url, extra_context)
  File "/home/Vieri/.local/lib/python3.6/site-packages/django/utils/decorators.py", line 43, in _wrapper
    return bound_method(*args, **kwargs)
  File "/home/Vieri/.local/lib/python3.6/site-packages/django/utils/decorators.py", line 130, in _wrapped_view
    response = view_func(request, *args, **kwargs)
  File "/home/Vieri/.local/lib/python3.6/site-packages/django/contrib/admin/options.py", line 1534, in changeform_view
    return self._changeform_view(request, object_id, form_url, extra_context)
  File "/home/Vieri/.local/lib/python3.6/site-packages/django/contrib/admin/options.py", line 1573, in _changeform_view
    form_validated = form.is_valid()
  File "/home/Vieri/.local/lib/python3.6/site-packages/django/forms/forms.py", line 177, in is_valid
    return self.is_bound and not self.errors
  File "/home/Vieri/.local/lib/python3.6/site-packages/django/forms/forms.py", line 172, in errors
    self.full_clean()
  File "/home/Vieri/.local/lib/python3.6/site-packages/django/forms/forms.py", line 376, in full_clean
    self._post_clean()
  File "/home/Vieri/.local/lib/python3.6/site-packages/django/forms/models.py", line 407, in _post_clean
    self._update_errors(e)
  File "/home/Vieri/.local/lib/python3.6/site-packages/django/forms/models.py", line 381, in _update_errors
    self.add_error(None, errors)
  File "/home/Vieri/.local/lib/python3.6/site-packages/django/forms/forms.py", line 346, in add_error
    "'%s' has no field named '%s'." % (self.__class__.__name__, field))
ValueError: 'ProductionFormForm' has no field named 'user_group'.
ERROR 2021-10-14 11:51:30,789 basehttp 753816 140020707989248 "POST /admin/form_produksi/productionform/add/ HTTP/1.1" 500 147940
WARNING 2021-10-14 12:39:16,949 basehttp 754058 140022815389440 "   TZ         .    I¨À )z» zÚf Ò~Uñi»©                ÃÐ¢|¦v½óOÑËÜ®Ëd" 400 -
WARNING 2021-10-14 13:55:49,433 basehttp 754058 140021403203328 "  /*à     Cookie: mstshash=Administr" 400 -
ERROR 2021-10-14 14:12:46,482 basehttp 756035 140059781080832 You're accessing the development server over HTTPS, but it only supports HTTP.

ERROR 2021-10-14 14:36:23,645 log 756778 139969754556160 Internal Server Error: /admin/form_produksi/productionform/17686/change/
Traceback (most recent call last):
  File "/home/Vieri/.local/lib/python3.6/site-packages/django/db/models/fields/related_descriptors.py", line 402, in __get__
    rel_obj = self.related.get_cached_value(instance)
  File "/home/Vieri/.local/lib/python3.6/site-packages/django/db/models/fields/mixins.py", line 15, in get_cached_value
    return instance._state.fields_cache[cache_name]
KeyError: 'groupprofile'

During handling of the above exception, another exception occurred:

Traceback (most recent call last):
  File "/home/Vieri/.local/lib/python3.6/site-packages/django/db/backends/utils.py", line 84, in _execute
    return self.cursor.execute(sql, params)
  File "/home/Vieri/.local/lib/python3.6/site-packages/django/db/backends/mysql/base.py", line 73, in execute
    return self.cursor.execute(query, args)
  File "/home/Vieri/.local/lib/python3.6/site-packages/MySQLdb/cursors.py", line 206, in execute
    res = self._query(query)
  File "/home/Vieri/.local/lib/python3.6/site-packages/MySQLdb/cursors.py", line 319, in _query
    db.query(q)
  File "/home/Vieri/.local/lib/python3.6/site-packages/MySQLdb/connections.py", line 259, in query
    _mysql.connection.query(self, query)
MySQLdb._exceptions.OperationalError: (1054, "Unknown column 'masterdata_groupprofile.daily_working_hour' in 'field list'")

The above exception was the direct cause of the following exception:

Traceback (most recent call last):
  File "/home/Vieri/.local/lib/python3.6/site-packages/django/core/handlers/exception.py", line 47, in inner
    response = get_response(request)
  File "/home/Vieri/.local/lib/python3.6/site-packages/django/core/handlers/base.py", line 181, in _get_response
    response = wrapped_callback(request, *callback_args, **callback_kwargs)
  File "/home/Vieri/.local/lib/python3.6/site-packages/django/contrib/admin/options.py", line 614, in wrapper
    return self.admin_site.admin_view(view)(*args, **kwargs)
  File "/home/Vieri/.local/lib/python3.6/site-packages/django/utils/decorators.py", line 130, in _wrapped_view
    response = view_func(request, *args, **kwargs)
  File "/home/Vieri/.local/lib/python3.6/site-packages/django/views/decorators/cache.py", line 44, in _wrapped_view_func
    response = view_func(request, *args, **kwargs)
  File "/home/Vieri/.local/lib/python3.6/site-packages/django/contrib/admin/sites.py", line 233, in inner
    return view(request, *args, **kwargs)
  File "/home/Vieri/.local/lib/python3.6/site-packages/django/contrib/admin/options.py", line 1656, in change_view
    return self.changeform_view(request, object_id, form_url, extra_context)
  File "/home/Vieri/.local/lib/python3.6/site-packages/django/utils/decorators.py", line 43, in _wrapper
    return bound_method(*args, **kwargs)
  File "/home/Vieri/.local/lib/python3.6/site-packages/django/utils/decorators.py", line 130, in _wrapped_view
    response = view_func(request, *args, **kwargs)
  File "/home/Vieri/.local/lib/python3.6/site-packages/django/contrib/admin/options.py", line 1534, in changeform_view
    return self._changeform_view(request, object_id, form_url, extra_context)
  File "/home/Vieri/.local/lib/python3.6/site-packages/django/contrib/admin/options.py", line 1580, in _changeform_view
    self.save_model(request, new_object, form, not add)
  File "/home/Vieri/project_dir/oee_impc/form_produksi/admin.py", line 1430, in save_model
    obj.save()
  File "/home/Vieri/project_dir/oee_impc/form_produksi/models.py", line 312, in save
    self.normalized_date = self.start_time - self.user_group.groupprofile.shift_hour
  File "/home/Vieri/.local/lib/python3.6/site-packages/django/db/models/fields/related_descriptors.py", line 410, in __get__
    rel_obj = self.get_queryset(instance=instance).get(**filter_args)
  File "/home/Vieri/.local/lib/python3.6/site-packages/django/db/models/query.py", line 425, in get
    num = len(clone)
  File "/home/Vieri/.local/lib/python3.6/site-packages/django/db/models/query.py", line 269, in __len__
    self._fetch_all()
  File "/home/Vieri/.local/lib/python3.6/site-packages/django/db/models/query.py", line 1308, in _fetch_all
    self._result_cache = list(self._iterable_class(self))
  File "/home/Vieri/.local/lib/python3.6/site-packages/django/db/models/query.py", line 53, in __iter__
    results = compiler.execute_sql(chunked_fetch=self.chunked_fetch, chunk_size=self.chunk_size)
  File "/home/Vieri/.local/lib/python3.6/site-packages/django/db/models/sql/compiler.py", line 1156, in execute_sql
    cursor.execute(sql, params)
  File "/home/Vieri/.local/lib/python3.6/site-packages/django/db/backends/utils.py", line 98, in execute
    return super().execute(sql, params)
  File "/home/Vieri/.local/lib/python3.6/site-packages/django/db/backends/utils.py", line 66, in execute
    return self._execute_with_wrappers(sql, params, many=False, executor=self._execute)
  File "/home/Vieri/.local/lib/python3.6/site-packages/django/db/backends/utils.py", line 75, in _execute_with_wrappers
    return executor(sql, params, many, context)
  File "/home/Vieri/.local/lib/python3.6/site-packages/django/db/backends/utils.py", line 84, in _execute
    return self.cursor.execute(sql, params)
  File "/home/Vieri/.local/lib/python3.6/site-packages/django/db/utils.py", line 90, in __exit__
    raise dj_exc_value.with_traceback(traceback) from exc_value
  File "/home/Vieri/.local/lib/python3.6/site-packages/django/db/backends/utils.py", line 84, in _execute
    return self.cursor.execute(sql, params)
  File "/home/Vieri/.local/lib/python3.6/site-packages/django/db/backends/mysql/base.py", line 73, in execute
    return self.cursor.execute(query, args)
  File "/home/Vieri/.local/lib/python3.6/site-packages/MySQLdb/cursors.py", line 206, in execute
    res = self._query(query)
  File "/home/Vieri/.local/lib/python3.6/site-packages/MySQLdb/cursors.py", line 319, in _query
    db.query(q)
  File "/home/Vieri/.local/lib/python3.6/site-packages/MySQLdb/connections.py", line 259, in query
    _mysql.connection.query(self, query)
django.db.utils.OperationalError: (1054, "Unknown column 'masterdata_groupprofile.daily_working_hour' in 'field list'")
ERROR 2021-10-14 14:36:23,691 basehttp 756778 139969754556160 "POST /admin/form_produksi/productionform/17686/change/?_changelist_filters=q%3DJ0021 HTTP/1.1" 500 228534
ERROR 2021-10-14 14:36:27,162 log 756778 139969754556160 Internal Server Error: /admin/form_produksi/productionform/17686/change/
Traceback (most recent call last):
  File "/home/Vieri/.local/lib/python3.6/site-packages/django/db/models/fields/related_descriptors.py", line 402, in __get__
    rel_obj = self.related.get_cached_value(instance)
  File "/home/Vieri/.local/lib/python3.6/site-packages/django/db/models/fields/mixins.py", line 15, in get_cached_value
    return instance._state.fields_cache[cache_name]
KeyError: 'groupprofile'

During handling of the above exception, another exception occurred:

Traceback (most recent call last):
  File "/home/Vieri/.local/lib/python3.6/site-packages/django/db/backends/utils.py", line 84, in _execute
    return self.cursor.execute(sql, params)
  File "/home/Vieri/.local/lib/python3.6/site-packages/django/db/backends/mysql/base.py", line 73, in execute
    return self.cursor.execute(query, args)
  File "/home/Vieri/.local/lib/python3.6/site-packages/MySQLdb/cursors.py", line 206, in execute
    res = self._query(query)
  File "/home/Vieri/.local/lib/python3.6/site-packages/MySQLdb/cursors.py", line 319, in _query
    db.query(q)
  File "/home/Vieri/.local/lib/python3.6/site-packages/MySQLdb/connections.py", line 259, in query
    _mysql.connection.query(self, query)
MySQLdb._exceptions.OperationalError: (1054, "Unknown column 'masterdata_groupprofile.daily_working_hour' in 'field list'")

The above exception was the direct cause of the following exception:

Traceback (most recent call last):
  File "/home/Vieri/.local/lib/python3.6/site-packages/django/core/handlers/exception.py", line 47, in inner
    response = get_response(request)
  File "/home/Vieri/.local/lib/python3.6/site-packages/django/core/handlers/base.py", line 181, in _get_response
    response = wrapped_callback(request, *callback_args, **callback_kwargs)
  File "/home/Vieri/.local/lib/python3.6/site-packages/django/contrib/admin/options.py", line 614, in wrapper
    return self.admin_site.admin_view(view)(*args, **kwargs)
  File "/home/Vieri/.local/lib/python3.6/site-packages/django/utils/decorators.py", line 130, in _wrapped_view
    response = view_func(request, *args, **kwargs)
  File "/home/Vieri/.local/lib/python3.6/site-packages/django/views/decorators/cache.py", line 44, in _wrapped_view_func
    response = view_func(request, *args, **kwargs)
  File "/home/Vieri/.local/lib/python3.6/site-packages/django/contrib/admin/sites.py", line 233, in inner
    return view(request, *args, **kwargs)
  File "/home/Vieri/.local/lib/python3.6/site-packages/django/contrib/admin/options.py", line 1656, in change_view
    return self.changeform_view(request, object_id, form_url, extra_context)
  File "/home/Vieri/.local/lib/python3.6/site-packages/django/utils/decorators.py", line 43, in _wrapper
    return bound_method(*args, **kwargs)
  File "/home/Vieri/.local/lib/python3.6/site-packages/django/utils/decorators.py", line 130, in _wrapped_view
    response = view_func(request, *args, **kwargs)
  File "/home/Vieri/.local/lib/python3.6/site-packages/django/contrib/admin/options.py", line 1534, in changeform_view
    return self._changeform_view(request, object_id, form_url, extra_context)
  File "/home/Vieri/.local/lib/python3.6/site-packages/django/contrib/admin/options.py", line 1580, in _changeform_view
    self.save_model(request, new_object, form, not add)
  File "/home/Vieri/project_dir/oee_impc/form_produksi/admin.py", line 1430, in save_model
    obj.save()
  File "/home/Vieri/project_dir/oee_impc/form_produksi/models.py", line 312, in save
    self.normalized_date = self.start_time - self.user_group.groupprofile.shift_hour
  File "/home/Vieri/.local/lib/python3.6/site-packages/django/db/models/fields/related_descriptors.py", line 410, in __get__
    rel_obj = self.get_queryset(instance=instance).get(**filter_args)
  File "/home/Vieri/.local/lib/python3.6/site-packages/django/db/models/query.py", line 425, in get
    num = len(clone)
  File "/home/Vieri/.local/lib/python3.6/site-packages/django/db/models/query.py", line 269, in __len__
    self._fetch_all()
  File "/home/Vieri/.local/lib/python3.6/site-packages/django/db/models/query.py", line 1308, in _fetch_all
    self._result_cache = list(self._iterable_class(self))
  File "/home/Vieri/.local/lib/python3.6/site-packages/django/db/models/query.py", line 53, in __iter__
    results = compiler.execute_sql(chunked_fetch=self.chunked_fetch, chunk_size=self.chunk_size)
  File "/home/Vieri/.local/lib/python3.6/site-packages/django/db/models/sql/compiler.py", line 1156, in execute_sql
    cursor.execute(sql, params)
  File "/home/Vieri/.local/lib/python3.6/site-packages/django/db/backends/utils.py", line 98, in execute
    return super().execute(sql, params)
  File "/home/Vieri/.local/lib/python3.6/site-packages/django/db/backends/utils.py", line 66, in execute
    return self._execute_with_wrappers(sql, params, many=False, executor=self._execute)
  File "/home/Vieri/.local/lib/python3.6/site-packages/django/db/backends/utils.py", line 75, in _execute_with_wrappers
    return executor(sql, params, many, context)
  File "/home/Vieri/.local/lib/python3.6/site-packages/django/db/backends/utils.py", line 84, in _execute
    return self.cursor.execute(sql, params)
  File "/home/Vieri/.local/lib/python3.6/site-packages/django/db/utils.py", line 90, in __exit__
    raise dj_exc_value.with_traceback(traceback) from exc_value
  File "/home/Vieri/.local/lib/python3.6/site-packages/django/db/backends/utils.py", line 84, in _execute
    return self.cursor.execute(sql, params)
  File "/home/Vieri/.local/lib/python3.6/site-packages/django/db/backends/mysql/base.py", line 73, in execute
    return self.cursor.execute(query, args)
  File "/home/Vieri/.local/lib/python3.6/site-packages/MySQLdb/cursors.py", line 206, in execute
    res = self._query(query)
  File "/home/Vieri/.local/lib/python3.6/site-packages/MySQLdb/cursors.py", line 319, in _query
    db.query(q)
  File "/home/Vieri/.local/lib/python3.6/site-packages/MySQLdb/connections.py", line 259, in query
    _mysql.connection.query(self, query)
django.db.utils.OperationalError: (1054, "Unknown column 'masterdata_groupprofile.daily_working_hour' in 'field list'")
ERROR 2021-10-14 14:36:27,291 basehttp 756778 139969754556160 "POST /admin/form_produksi/productionform/17686/change/?_changelist_filters=q%3DJ0021 HTTP/1.1" 500 228534
ERROR 2021-10-14 17:15:27,669 exception 758957 140562871088896 Invalid HTTP_HOST header: 'www.google.com'. You may need to add 'www.google.com' to ALLOWED_HOSTS.
WARNING 2021-10-14 17:15:27,730 log 758957 140562871088896 Bad Request: /http:/www.google.com/
WARNING 2021-10-14 17:15:27,730 basehttp 758957 140562871088896 "GET http://www.google.com/ HTTP/1.0" 400 63792
