ERROR 2021-11-02 11:23:21,493 log 563620 139725436413696 Internal Server Error: /admin/form_produksi/reportdowntimepermesin/12/change/
Traceback (most recent call last):
  File "/home/Vieri/.local/lib/python3.6/site-packages/django/core/handlers/exception.py", line 47, in inner
    response = get_response(request)
  File "/home/Vieri/.local/lib/python3.6/site-packages/django/core/handlers/base.py", line 181, in _get_response
    response = wrapped_callback(request, *callback_args, **callback_kwargs)
  File "/home/Vieri/.local/lib/python3.6/site-packages/django/contrib/admin/options.py", line 614, in wrapper
    return self.admin_site.admin_view(view)(*args, **kwargs)
  File "/home/Vieri/.local/lib/python3.6/site-packages/django/utils/decorators.py", line 130, in _wrapped_view
    response = view_func(request, *args, **kwargs)
  File "/home/Vieri/.local/lib/python3.6/site-packages/django/views/decorators/cache.py", line 44, in _wrapped_view_func
    response = view_func(request, *args, **kwargs)
  File "/home/Vieri/.local/lib/python3.6/site-packages/django/contrib/admin/sites.py", line 233, in inner
    return view(request, *args, **kwargs)
  File "/home/Vieri/project_dir/oee_impc/form_produksi/admin.py", line 1945, in change_view
    form_shift = form_shift.filter(**q_params)
  File "/home/Vieri/.local/lib/python3.6/site-packages/django/db/models/query.py", line 942, in filter
    return self._filter_or_exclude(False, *args, **kwargs)
  File "/home/Vieri/.local/lib/python3.6/site-packages/django/db/models/query.py", line 962, in _filter_or_exclude
    clone._filter_or_exclude_inplace(negate, *args, **kwargs)
  File "/home/Vieri/.local/lib/python3.6/site-packages/django/db/models/query.py", line 969, in _filter_or_exclude_inplace
    self._query.add_q(Q(*args, **kwargs))
  File "/home/Vieri/.local/lib/python3.6/site-packages/django/db/models/sql/query.py", line 1358, in add_q
    clause, _ = self._add_q(q_object, self.used_aliases)
  File "/home/Vieri/.local/lib/python3.6/site-packages/django/db/models/sql/query.py", line 1380, in _add_q
    split_subq=split_subq, check_filterable=check_filterable,
  File "/home/Vieri/.local/lib/python3.6/site-packages/django/db/models/sql/query.py", line 1319, in build_filter
    condition = self.build_lookup(lookups, col, value)
  File "/home/Vieri/.local/lib/python3.6/site-packages/django/db/models/sql/query.py", line 1150, in build_lookup
    lhs = self.try_transform(lhs, name)
  File "/home/Vieri/.local/lib/python3.6/site-packages/django/db/models/sql/query.py", line 1200, in try_transform
    "permitted%s" % (name, output_field.__name__, suggestion)
django.core.exceptions.FieldError: Unsupported lookup 'range' for DateTimeField or join on the field not permitted, perhaps you meant range or regex?
ERROR 2021-11-02 11:23:21,496 basehttp 563620 139725436413696 "GET /admin/form_produksi/reportdowntimepermesin/12/change/?normalized_date__range__gte=01%2F07%2F2021&normalized_date__range__lte=31%2F07%2F2021&user_group__id__exact=3 HTTP/1.1" 500 132702
ERROR 2021-11-02 11:23:29,989 log 563620 139725168158464 Internal Server Error: /admin/form_produksi/reportdowntimepermesin/12/change/
Traceback (most recent call last):
  File "/home/Vieri/.local/lib/python3.6/site-packages/django/core/handlers/exception.py", line 47, in inner
    response = get_response(request)
  File "/home/Vieri/.local/lib/python3.6/site-packages/django/core/handlers/base.py", line 181, in _get_response
    response = wrapped_callback(request, *callback_args, **callback_kwargs)
  File "/home/Vieri/.local/lib/python3.6/site-packages/django/contrib/admin/options.py", line 614, in wrapper
    return self.admin_site.admin_view(view)(*args, **kwargs)
  File "/home/Vieri/.local/lib/python3.6/site-packages/django/utils/decorators.py", line 130, in _wrapped_view
    response = view_func(request, *args, **kwargs)
  File "/home/Vieri/.local/lib/python3.6/site-packages/django/views/decorators/cache.py", line 44, in _wrapped_view_func
    response = view_func(request, *args, **kwargs)
  File "/home/Vieri/.local/lib/python3.6/site-packages/django/contrib/admin/sites.py", line 233, in inner
    return view(request, *args, **kwargs)
  File "/home/Vieri/project_dir/oee_impc/form_produksi/admin.py", line 1945, in change_view
    form_shift = form_shift.filter(**q_params)
  File "/home/Vieri/.local/lib/python3.6/site-packages/django/db/models/query.py", line 942, in filter
    return self._filter_or_exclude(False, *args, **kwargs)
  File "/home/Vieri/.local/lib/python3.6/site-packages/django/db/models/query.py", line 962, in _filter_or_exclude
    clone._filter_or_exclude_inplace(negate, *args, **kwargs)
  File "/home/Vieri/.local/lib/python3.6/site-packages/django/db/models/query.py", line 969, in _filter_or_exclude_inplace
    self._query.add_q(Q(*args, **kwargs))
  File "/home/Vieri/.local/lib/python3.6/site-packages/django/db/models/sql/query.py", line 1358, in add_q
    clause, _ = self._add_q(q_object, self.used_aliases)
  File "/home/Vieri/.local/lib/python3.6/site-packages/django/db/models/sql/query.py", line 1380, in _add_q
    split_subq=split_subq, check_filterable=check_filterable,
  File "/home/Vieri/.local/lib/python3.6/site-packages/django/db/models/sql/query.py", line 1319, in build_filter
    condition = self.build_lookup(lookups, col, value)
  File "/home/Vieri/.local/lib/python3.6/site-packages/django/db/models/sql/query.py", line 1150, in build_lookup
    lhs = self.try_transform(lhs, name)
  File "/home/Vieri/.local/lib/python3.6/site-packages/django/db/models/sql/query.py", line 1200, in try_transform
    "permitted%s" % (name, output_field.__name__, suggestion)
django.core.exceptions.FieldError: Unsupported lookup 'range' for DateTimeField or join on the field not permitted, perhaps you meant range or regex?
ERROR 2021-11-02 11:23:29,990 basehttp 563620 139725168158464 "GET /admin/form_produksi/reportdowntimepermesin/12/change/?normalized_date__range__gte=01%2F07%2F2021&normalized_date__range__lte=31%2F07%2F2021&user_group__id__exact=3 HTTP/1.1" 500 132702
ERROR 2021-11-02 13:40:54,055 log 568340 140002104514304 Internal Server Error: /admin/form_produksi/reportdowntimepermesin/13/change/
Traceback (most recent call last):
  File "/home/Vieri/.local/lib/python3.6/site-packages/django/core/handlers/exception.py", line 47, in inner
    response = get_response(request)
  File "/home/Vieri/.local/lib/python3.6/site-packages/django/core/handlers/base.py", line 181, in _get_response
    response = wrapped_callback(request, *callback_args, **callback_kwargs)
  File "/home/Vieri/.local/lib/python3.6/site-packages/django/contrib/admin/options.py", line 614, in wrapper
    return self.admin_site.admin_view(view)(*args, **kwargs)
  File "/home/Vieri/.local/lib/python3.6/site-packages/django/utils/decorators.py", line 130, in _wrapped_view
    response = view_func(request, *args, **kwargs)
  File "/home/Vieri/.local/lib/python3.6/site-packages/django/views/decorators/cache.py", line 44, in _wrapped_view_func
    response = view_func(request, *args, **kwargs)
  File "/home/Vieri/.local/lib/python3.6/site-packages/django/contrib/admin/sites.py", line 233, in inner
    return view(request, *args, **kwargs)
  File "/home/Vieri/project_dir/oee_impc/form_produksi/admin.py", line 1945, in change_view
    form_shift = form_shift.filter(**q_params)
  File "/home/Vieri/.local/lib/python3.6/site-packages/django/db/models/query.py", line 942, in filter
    return self._filter_or_exclude(False, *args, **kwargs)
  File "/home/Vieri/.local/lib/python3.6/site-packages/django/db/models/query.py", line 962, in _filter_or_exclude
    clone._filter_or_exclude_inplace(negate, *args, **kwargs)
  File "/home/Vieri/.local/lib/python3.6/site-packages/django/db/models/query.py", line 969, in _filter_or_exclude_inplace
    self._query.add_q(Q(*args, **kwargs))
  File "/home/Vieri/.local/lib/python3.6/site-packages/django/db/models/sql/query.py", line 1358, in add_q
    clause, _ = self._add_q(q_object, self.used_aliases)
  File "/home/Vieri/.local/lib/python3.6/site-packages/django/db/models/sql/query.py", line 1380, in _add_q
    split_subq=split_subq, check_filterable=check_filterable,
  File "/home/Vieri/.local/lib/python3.6/site-packages/django/db/models/sql/query.py", line 1319, in build_filter
    condition = self.build_lookup(lookups, col, value)
  File "/home/Vieri/.local/lib/python3.6/site-packages/django/db/models/sql/query.py", line 1150, in build_lookup
    lhs = self.try_transform(lhs, name)
  File "/home/Vieri/.local/lib/python3.6/site-packages/django/db/models/sql/query.py", line 1200, in try_transform
    "permitted%s" % (name, output_field.__name__, suggestion)
django.core.exceptions.FieldError: Unsupported lookup 'range' for DateTimeField or join on the field not permitted, perhaps you meant range or regex?
ERROR 2021-11-02 13:40:54,059 basehttp 568340 140002104514304 "GET /admin/form_produksi/reportdowntimepermesin/13/change/?normalized_date__range__gte=01%2F8%2F2021&normalized_date__range__lte=01%2F11%2F2021 HTTP/1.1" 500 131990
ERROR 2021-11-02 15:07:31,895 log 571043 140590311270144 Internal Server Error: /admin/form_produksi/productionform/21458/change/
Traceback (most recent call last):
  File "/home/Vieri/.local/lib/python3.6/site-packages/django/db/models/fields/related_descriptors.py", line 173, in __get__
    rel_obj = self.field.get_cached_value(instance)
  File "/home/Vieri/.local/lib/python3.6/site-packages/django/db/models/fields/mixins.py", line 15, in get_cached_value
    return instance._state.fields_cache[cache_name]
KeyError: 'no_kk'

During handling of the above exception, another exception occurred:

Traceback (most recent call last):
  File "/home/Vieri/.local/lib/python3.6/site-packages/django/db/backends/utils.py", line 84, in _execute
    return self.cursor.execute(sql, params)
  File "/home/Vieri/.local/lib/python3.6/site-packages/django/db/backends/mysql/base.py", line 73, in execute
    return self.cursor.execute(query, args)
  File "/home/Vieri/.local/lib/python3.6/site-packages/MySQLdb/cursors.py", line 206, in execute
    res = self._query(query)
  File "/home/Vieri/.local/lib/python3.6/site-packages/MySQLdb/cursors.py", line 319, in _query
    db.query(q)
  File "/home/Vieri/.local/lib/python3.6/site-packages/MySQLdb/connections.py", line 259, in query
    _mysql.connection.query(self, query)
MySQLdb._exceptions.OperationalError: (1054, "Unknown column 'form_produksi_kk.item_example_id' in 'field list'")

The above exception was the direct cause of the following exception:

Traceback (most recent call last):
  File "/home/Vieri/.local/lib/python3.6/site-packages/django/core/handlers/exception.py", line 47, in inner
    response = get_response(request)
  File "/home/Vieri/.local/lib/python3.6/site-packages/django/core/handlers/base.py", line 181, in _get_response
    response = wrapped_callback(request, *callback_args, **callback_kwargs)
  File "/home/Vieri/.local/lib/python3.6/site-packages/django/contrib/admin/options.py", line 614, in wrapper
    return self.admin_site.admin_view(view)(*args, **kwargs)
  File "/home/Vieri/.local/lib/python3.6/site-packages/django/utils/decorators.py", line 130, in _wrapped_view
    response = view_func(request, *args, **kwargs)
  File "/home/Vieri/.local/lib/python3.6/site-packages/django/views/decorators/cache.py", line 44, in _wrapped_view_func
    response = view_func(request, *args, **kwargs)
  File "/home/Vieri/.local/lib/python3.6/site-packages/django/contrib/admin/sites.py", line 233, in inner
    return view(request, *args, **kwargs)
  File "/home/Vieri/.local/lib/python3.6/site-packages/django/contrib/admin/options.py", line 1656, in change_view
    return self.changeform_view(request, object_id, form_url, extra_context)
  File "/home/Vieri/.local/lib/python3.6/site-packages/django/utils/decorators.py", line 43, in _wrapper
    return bound_method(*args, **kwargs)
  File "/home/Vieri/.local/lib/python3.6/site-packages/django/utils/decorators.py", line 130, in _wrapped_view
    response = view_func(request, *args, **kwargs)
  File "/home/Vieri/.local/lib/python3.6/site-packages/django/contrib/admin/options.py", line 1534, in changeform_view
    return self._changeform_view(request, object_id, form_url, extra_context)
  File "/home/Vieri/.local/lib/python3.6/site-packages/django/contrib/admin/options.py", line 1569, in _changeform_view
    request, obj, change=not add, fields=flatten_fieldsets(fieldsets)
  File "/home/Vieri/.local/lib/python3.6/site-packages/django/contrib/admin/options.py", line 683, in get_form
    if change and hasattr(request, 'user') and not self.has_change_permission(request, obj):
  File "/home/Vieri/project_dir/oee_impc/form_produksi/admin.py", line 1427, in has_change_permission
    return obj.no_kk.aktif == "1" and super().has_change_permission(request, obj)
  File "/home/Vieri/.local/lib/python3.6/site-packages/django/db/models/fields/related_descriptors.py", line 187, in __get__
    rel_obj = self.get_object(instance)
  File "/home/Vieri/.local/lib/python3.6/site-packages/django/db/models/fields/related_descriptors.py", line 154, in get_object
    return qs.get(self.field.get_reverse_related_filter(instance))
  File "/home/Vieri/.local/lib/python3.6/site-packages/django/db/models/query.py", line 425, in get
    num = len(clone)
  File "/home/Vieri/.local/lib/python3.6/site-packages/django/db/models/query.py", line 269, in __len__
    self._fetch_all()
  File "/home/Vieri/.local/lib/python3.6/site-packages/django/db/models/query.py", line 1308, in _fetch_all
    self._result_cache = list(self._iterable_class(self))
  File "/home/Vieri/.local/lib/python3.6/site-packages/django/db/models/query.py", line 53, in __iter__
    results = compiler.execute_sql(chunked_fetch=self.chunked_fetch, chunk_size=self.chunk_size)
  File "/home/Vieri/.local/lib/python3.6/site-packages/django/db/models/sql/compiler.py", line 1156, in execute_sql
    cursor.execute(sql, params)
  File "/home/Vieri/.local/lib/python3.6/site-packages/django/db/backends/utils.py", line 98, in execute
    return super().execute(sql, params)
  File "/home/Vieri/.local/lib/python3.6/site-packages/django/db/backends/utils.py", line 66, in execute
    return self._execute_with_wrappers(sql, params, many=False, executor=self._execute)
  File "/home/Vieri/.local/lib/python3.6/site-packages/django/db/backends/utils.py", line 75, in _execute_with_wrappers
    return executor(sql, params, many, context)
  File "/home/Vieri/.local/lib/python3.6/site-packages/django/db/backends/utils.py", line 84, in _execute
    return self.cursor.execute(sql, params)
  File "/home/Vieri/.local/lib/python3.6/site-packages/django/db/utils.py", line 90, in __exit__
    raise dj_exc_value.with_traceback(traceback) from exc_value
  File "/home/Vieri/.local/lib/python3.6/site-packages/django/db/backends/utils.py", line 84, in _execute
    return self.cursor.execute(sql, params)
  File "/home/Vieri/.local/lib/python3.6/site-packages/django/db/backends/mysql/base.py", line 73, in execute
    return self.cursor.execute(query, args)
  File "/home/Vieri/.local/lib/python3.6/site-packages/MySQLdb/cursors.py", line 206, in execute
    res = self._query(query)
  File "/home/Vieri/.local/lib/python3.6/site-packages/MySQLdb/cursors.py", line 319, in _query
    db.query(q)
  File "/home/Vieri/.local/lib/python3.6/site-packages/MySQLdb/connections.py", line 259, in query
    _mysql.connection.query(self, query)
django.db.utils.OperationalError: (1054, "Unknown column 'form_produksi_kk.item_example_id' in 'field list'")
ERROR 2021-11-02 15:07:32,001 basehttp 571043 140590311270144 "GET /admin/form_produksi/productionform/21458/change/?_changelist_filters=machine__id__exact%3D63%26user_group__id__exact%3D1%26normalized_date__range__gte%3D02%252F11%252F2021%26normalized_date__range__lte%3D HTTP/1.1" 500 228291
ERROR 2021-11-02 15:07:32,580 log 571043 140590300354304 Internal Server Error: /admin/form_produksi/productionform/21128/change/
Traceback (most recent call last):
  File "/home/Vieri/.local/lib/python3.6/site-packages/django/db/models/fields/related_descriptors.py", line 173, in __get__
    rel_obj = self.field.get_cached_value(instance)
  File "/home/Vieri/.local/lib/python3.6/site-packages/django/db/models/fields/mixins.py", line 15, in get_cached_value
    return instance._state.fields_cache[cache_name]
KeyError: 'no_kk'

During handling of the above exception, another exception occurred:

Traceback (most recent call last):
  File "/home/Vieri/.local/lib/python3.6/site-packages/django/db/backends/utils.py", line 84, in _execute
    return self.cursor.execute(sql, params)
  File "/home/Vieri/.local/lib/python3.6/site-packages/django/db/backends/mysql/base.py", line 73, in execute
    return self.cursor.execute(query, args)
  File "/home/Vieri/.local/lib/python3.6/site-packages/MySQLdb/cursors.py", line 206, in execute
    res = self._query(query)
  File "/home/Vieri/.local/lib/python3.6/site-packages/MySQLdb/cursors.py", line 319, in _query
    db.query(q)
  File "/home/Vieri/.local/lib/python3.6/site-packages/MySQLdb/connections.py", line 259, in query
    _mysql.connection.query(self, query)
MySQLdb._exceptions.OperationalError: (1054, "Unknown column 'form_produksi_kk.item_example_id' in 'field list'")

The above exception was the direct cause of the following exception:

Traceback (most recent call last):
  File "/home/Vieri/.local/lib/python3.6/site-packages/django/core/handlers/exception.py", line 47, in inner
    response = get_response(request)
  File "/home/Vieri/.local/lib/python3.6/site-packages/django/core/handlers/base.py", line 181, in _get_response
    response = wrapped_callback(request, *callback_args, **callback_kwargs)
  File "/home/Vieri/.local/lib/python3.6/site-packages/django/contrib/admin/options.py", line 614, in wrapper
    return self.admin_site.admin_view(view)(*args, **kwargs)
  File "/home/Vieri/.local/lib/python3.6/site-packages/django/utils/decorators.py", line 130, in _wrapped_view
    response = view_func(request, *args, **kwargs)
  File "/home/Vieri/.local/lib/python3.6/site-packages/django/views/decorators/cache.py", line 44, in _wrapped_view_func
    response = view_func(request, *args, **kwargs)
  File "/home/Vieri/.local/lib/python3.6/site-packages/django/contrib/admin/sites.py", line 233, in inner
    return view(request, *args, **kwargs)
  File "/home/Vieri/.local/lib/python3.6/site-packages/django/contrib/admin/options.py", line 1656, in change_view
    return self.changeform_view(request, object_id, form_url, extra_context)
  File "/home/Vieri/.local/lib/python3.6/site-packages/django/utils/decorators.py", line 43, in _wrapper
    return bound_method(*args, **kwargs)
  File "/home/Vieri/.local/lib/python3.6/site-packages/django/utils/decorators.py", line 130, in _wrapped_view
    response = view_func(request, *args, **kwargs)
  File "/home/Vieri/.local/lib/python3.6/site-packages/django/contrib/admin/options.py", line 1534, in changeform_view
    return self._changeform_view(request, object_id, form_url, extra_context)
  File "/home/Vieri/.local/lib/python3.6/site-packages/django/contrib/admin/options.py", line 1569, in _changeform_view
    request, obj, change=not add, fields=flatten_fieldsets(fieldsets)
  File "/home/Vieri/.local/lib/python3.6/site-packages/django/contrib/admin/options.py", line 683, in get_form
    if change and hasattr(request, 'user') and not self.has_change_permission(request, obj):
  File "/home/Vieri/project_dir/oee_impc/form_produksi/admin.py", line 1427, in has_change_permission
    return obj.no_kk.aktif == "1" and super().has_change_permission(request, obj)
  File "/home/Vieri/.local/lib/python3.6/site-packages/django/db/models/fields/related_descriptors.py", line 187, in __get__
    rel_obj = self.get_object(instance)
  File "/home/Vieri/.local/lib/python3.6/site-packages/django/db/models/fields/related_descriptors.py", line 154, in get_object
    return qs.get(self.field.get_reverse_related_filter(instance))
  File "/home/Vieri/.local/lib/python3.6/site-packages/django/db/models/query.py", line 425, in get
    num = len(clone)
  File "/home/Vieri/.local/lib/python3.6/site-packages/django/db/models/query.py", line 269, in __len__
    self._fetch_all()
  File "/home/Vieri/.local/lib/python3.6/site-packages/django/db/models/query.py", line 1308, in _fetch_all
    self._result_cache = list(self._iterable_class(self))
  File "/home/Vieri/.local/lib/python3.6/site-packages/django/db/models/query.py", line 53, in __iter__
    results = compiler.execute_sql(chunked_fetch=self.chunked_fetch, chunk_size=self.chunk_size)
  File "/home/Vieri/.local/lib/python3.6/site-packages/django/db/models/sql/compiler.py", line 1156, in execute_sql
    cursor.execute(sql, params)
  File "/home/Vieri/.local/lib/python3.6/site-packages/django/db/backends/utils.py", line 98, in execute
    return super().execute(sql, params)
  File "/home/Vieri/.local/lib/python3.6/site-packages/django/db/backends/utils.py", line 66, in execute
    return self._execute_with_wrappers(sql, params, many=False, executor=self._execute)
  File "/home/Vieri/.local/lib/python3.6/site-packages/django/db/backends/utils.py", line 75, in _execute_with_wrappers
    return executor(sql, params, many, context)
  File "/home/Vieri/.local/lib/python3.6/site-packages/django/db/backends/utils.py", line 84, in _execute
    return self.cursor.execute(sql, params)
  File "/home/Vieri/.local/lib/python3.6/site-packages/django/db/utils.py", line 90, in __exit__
    raise dj_exc_value.with_traceback(traceback) from exc_value
  File "/home/Vieri/.local/lib/python3.6/site-packages/django/db/backends/utils.py", line 84, in _execute
    return self.cursor.execute(sql, params)
  File "/home/Vieri/.local/lib/python3.6/site-packages/django/db/backends/mysql/base.py", line 73, in execute
    return self.cursor.execute(query, args)
  File "/home/Vieri/.local/lib/python3.6/site-packages/MySQLdb/cursors.py", line 206, in execute
    res = self._query(query)
  File "/home/Vieri/.local/lib/python3.6/site-packages/MySQLdb/cursors.py", line 319, in _query
    db.query(q)
  File "/home/Vieri/.local/lib/python3.6/site-packages/MySQLdb/connections.py", line 259, in query
    _mysql.connection.query(self, query)
django.db.utils.OperationalError: (1054, "Unknown column 'form_produksi_kk.item_example_id' in 'field list'")
ERROR 2021-11-02 15:07:32,599 basehttp 571043 140590300354304 "GET /admin/form_produksi/productionform/21128/change/?_changelist_filters=q%3DWO2.210201 HTTP/1.1" 500 226122
ERROR 2021-11-02 15:07:39,631 log 571043 140590300354304 Internal Server Error: /admin/form_produksi/productionform/21128/change/
Traceback (most recent call last):
  File "/home/Vieri/.local/lib/python3.6/site-packages/django/db/models/fields/related_descriptors.py", line 173, in __get__
    rel_obj = self.field.get_cached_value(instance)
  File "/home/Vieri/.local/lib/python3.6/site-packages/django/db/models/fields/mixins.py", line 15, in get_cached_value
    return instance._state.fields_cache[cache_name]
KeyError: 'no_kk'

During handling of the above exception, another exception occurred:

Traceback (most recent call last):
  File "/home/Vieri/.local/lib/python3.6/site-packages/django/db/backends/utils.py", line 84, in _execute
    return self.cursor.execute(sql, params)
  File "/home/Vieri/.local/lib/python3.6/site-packages/django/db/backends/mysql/base.py", line 73, in execute
    return self.cursor.execute(query, args)
  File "/home/Vieri/.local/lib/python3.6/site-packages/MySQLdb/cursors.py", line 206, in execute
    res = self._query(query)
  File "/home/Vieri/.local/lib/python3.6/site-packages/MySQLdb/cursors.py", line 319, in _query
    db.query(q)
  File "/home/Vieri/.local/lib/python3.6/site-packages/MySQLdb/connections.py", line 259, in query
    _mysql.connection.query(self, query)
MySQLdb._exceptions.OperationalError: (1054, "Unknown column 'form_produksi_kk.item_example_id' in 'field list'")

The above exception was the direct cause of the following exception:

Traceback (most recent call last):
  File "/home/Vieri/.local/lib/python3.6/site-packages/django/core/handlers/exception.py", line 47, in inner
    response = get_response(request)
  File "/home/Vieri/.local/lib/python3.6/site-packages/django/core/handlers/base.py", line 181, in _get_response
    response = wrapped_callback(request, *callback_args, **callback_kwargs)
  File "/home/Vieri/.local/lib/python3.6/site-packages/django/contrib/admin/options.py", line 614, in wrapper
    return self.admin_site.admin_view(view)(*args, **kwargs)
  File "/home/Vieri/.local/lib/python3.6/site-packages/django/utils/decorators.py", line 130, in _wrapped_view
    response = view_func(request, *args, **kwargs)
  File "/home/Vieri/.local/lib/python3.6/site-packages/django/views/decorators/cache.py", line 44, in _wrapped_view_func
    response = view_func(request, *args, **kwargs)
  File "/home/Vieri/.local/lib/python3.6/site-packages/django/contrib/admin/sites.py", line 233, in inner
    return view(request, *args, **kwargs)
  File "/home/Vieri/.local/lib/python3.6/site-packages/django/contrib/admin/options.py", line 1656, in change_view
    return self.changeform_view(request, object_id, form_url, extra_context)
  File "/home/Vieri/.local/lib/python3.6/site-packages/django/utils/decorators.py", line 43, in _wrapper
    return bound_method(*args, **kwargs)
  File "/home/Vieri/.local/lib/python3.6/site-packages/django/utils/decorators.py", line 130, in _wrapped_view
    response = view_func(request, *args, **kwargs)
  File "/home/Vieri/.local/lib/python3.6/site-packages/django/contrib/admin/options.py", line 1534, in changeform_view
    return self._changeform_view(request, object_id, form_url, extra_context)
  File "/home/Vieri/.local/lib/python3.6/site-packages/django/contrib/admin/options.py", line 1569, in _changeform_view
    request, obj, change=not add, fields=flatten_fieldsets(fieldsets)
  File "/home/Vieri/.local/lib/python3.6/site-packages/django/contrib/admin/options.py", line 683, in get_form
    if change and hasattr(request, 'user') and not self.has_change_permission(request, obj):
  File "/home/Vieri/project_dir/oee_impc/form_produksi/admin.py", line 1427, in has_change_permission
    return obj.no_kk.aktif == "1" and super().has_change_permission(request, obj)
  File "/home/Vieri/.local/lib/python3.6/site-packages/django/db/models/fields/related_descriptors.py", line 187, in __get__
    rel_obj = self.get_object(instance)
  File "/home/Vieri/.local/lib/python3.6/site-packages/django/db/models/fields/related_descriptors.py", line 154, in get_object
    return qs.get(self.field.get_reverse_related_filter(instance))
  File "/home/Vieri/.local/lib/python3.6/site-packages/django/db/models/query.py", line 425, in get
    num = len(clone)
  File "/home/Vieri/.local/lib/python3.6/site-packages/django/db/models/query.py", line 269, in __len__
    self._fetch_all()
  File "/home/Vieri/.local/lib/python3.6/site-packages/django/db/models/query.py", line 1308, in _fetch_all
    self._result_cache = list(self._iterable_class(self))
  File "/home/Vieri/.local/lib/python3.6/site-packages/django/db/models/query.py", line 53, in __iter__
    results = compiler.execute_sql(chunked_fetch=self.chunked_fetch, chunk_size=self.chunk_size)
  File "/home/Vieri/.local/lib/python3.6/site-packages/django/db/models/sql/compiler.py", line 1156, in execute_sql
    cursor.execute(sql, params)
  File "/home/Vieri/.local/lib/python3.6/site-packages/django/db/backends/utils.py", line 98, in execute
    return super().execute(sql, params)
  File "/home/Vieri/.local/lib/python3.6/site-packages/django/db/backends/utils.py", line 66, in execute
    return self._execute_with_wrappers(sql, params, many=False, executor=self._execute)
  File "/home/Vieri/.local/lib/python3.6/site-packages/django/db/backends/utils.py", line 75, in _execute_with_wrappers
    return executor(sql, params, many, context)
  File "/home/Vieri/.local/lib/python3.6/site-packages/django/db/backends/utils.py", line 84, in _execute
    return self.cursor.execute(sql, params)
  File "/home/Vieri/.local/lib/python3.6/site-packages/django/db/utils.py", line 90, in __exit__
    raise dj_exc_value.with_traceback(traceback) from exc_value
  File "/home/Vieri/.local/lib/python3.6/site-packages/django/db/backends/utils.py", line 84, in _execute
    return self.cursor.execute(sql, params)
  File "/home/Vieri/.local/lib/python3.6/site-packages/django/db/backends/mysql/base.py", line 73, in execute
    return self.cursor.execute(query, args)
  File "/home/Vieri/.local/lib/python3.6/site-packages/MySQLdb/cursors.py", line 206, in execute
    res = self._query(query)
  File "/home/Vieri/.local/lib/python3.6/site-packages/MySQLdb/cursors.py", line 319, in _query
    db.query(q)
  File "/home/Vieri/.local/lib/python3.6/site-packages/MySQLdb/connections.py", line 259, in query
    _mysql.connection.query(self, query)
django.db.utils.OperationalError: (1054, "Unknown column 'form_produksi_kk.item_example_id' in 'field list'")
ERROR 2021-11-02 15:07:39,633 basehttp 571043 140590300354304 "GET /admin/form_produksi/productionform/21128/change/?_changelist_filters=q%3DWO2.210201 HTTP/1.1" 500 226122
ERROR 2021-11-02 16:06:15,246 basehttp 571701 140684724000512 You're accessing the development server over HTTPS, but it only supports HTTP.

ERROR 2021-11-02 16:50:58,061 exception 571701 140685117921024 Invalid HTTP_HOST header: 'www.google.com'. You may need to add 'www.google.com' to ALLOWED_HOSTS.
WARNING 2021-11-02 16:50:58,120 log 571701 140685117921024 Bad Request: /www.google.com:443
WARNING 2021-11-02 16:50:58,121 basehttp 571701 140685117921024 "CONNECT www.google.com:443 HTTP/1.1" 400 63758
